Workbook
Name Slicer_Days: #N/A
Name Slicer_Month: #N/A
Name Slicer_Weekday_weekend: #N/A

Sheet dashboard

Sheet Anamoly detection
F2: =_xlfn.QUARTILE.INC($J$4:$J$48,1) -> 1005 | G2: QI | I2: Anamoly detection table | P2: Row Labels | Q2: Sum of Total Count
F3: =_xlfn.QUARTILE.INC($J$4:$J$48,3) -> 1562 | G3: Q3 | I3: Date | J3: Count | K3: Outliers | L3: Normal | M3: Upper threshold | N3: Lower threshold | P3: 40544 | Q3: 985
I4: =P3 -> 40544 | J4: =Q3 -> 985 | K4: =IF(OR(J4<$G$7,J4>$G$8),J4,"") | L4: =IF(AND(J4>$G$7,J4<$G$8),J4,"") -> 985 | M4: 2397.5 | N4: 169.5 | P4: 40545 | Q4: 801
F5: IQR | G5: =F3-F2 -> 557 | I5: =P4 -> 40545 | J5: =Q4 -> 801 | K5: =IF(OR(J5<$G$7,J5>$G$8),J5,"") | L5: =IF(AND(J5>$G$7,J5<$G$8),J5,"") -> 801 | M5: 2397.5 | N5: 169.5 | P5: 40546 | Q5: 1349
I6: =P5 -> 40546 | J6: =Q5 -> 1349 | K6: =IF(OR(J6<$G$7,J6>$G$8),J6,"") | L6: =IF(AND(J6>$G$7,J6<$G$8),J6,"") -> 1349 | M6: 2397.5 | N6: 169.5 | P6: 40547 | Q6: 1562
F7: Lower threshold | G7: =F2-(1.5*(G5)) -> 169.5 | I7: =P6 -> 40547 | J7: =Q6 -> 1562 | K7: =IF(OR(J7<$G$7,J7>$G$8),J7,"") | L7: =IF(AND(J7>$G$7,J7<$G$8),J7,"") -> 1562 | M7: 2397.5 | N7: 169.5 | P7: 40548 | Q7: 1600
F8: Upper threshold | G8: =F3+(1.5*(G5)) -> 2397.5 | I8: =P7 -> 40548 | J8: =Q7 -> 1600 | K8: =IF(OR(J8<$G$7,J8>$G$8),J8,"") | L8: =IF(AND(J8>$G$7,J8<$G$8),J8,"") -> 1600 | M8: 2397.5 | N8: 169.5 | P8: 40549 | Q8: 1606
I9: =P8 -> 40549 | J9: =Q8 -> 1606 | K9: =IF(OR(J9<$G$7,J9>$G$8),J9,"") | L9: =IF(AND(J9>$G$7,J9<$G$8),J9,"") -> 1606 | M9: 2397.5 | N9: 169.5 | P9: 40550 | Q9: 1510
I10: =P9 -> 40550 | J10: =Q9 -> 1510 | K10: =IF(OR(J10<$G$7,J10>$G$8),J10,"") | L10: =IF(AND(J10>$G$7,J10<$G$8),J10,"") -> 1510 | M10: 2397.5 | N10: 169.5 | P10: 40551 | Q10: 959
I11: =P10 -> 40551 | J11: =Q10 -> 959 | K11: =IF(OR(J11<$G$7,J11>$G$8),J11,"") | L11: =IF(AND(J11>$G$7,J11<$G$8),J11,"") -> 959 | M11: 2397.5 | N11: 169.5 | P11: 40552 | Q11: 822
I12: =P11 -> 40552 | J12: =Q11 -> 822 | K12: =IF(OR(J12<$G$7,J12>$G$8),J12,"") | L12: =IF(AND(J12>$G$7,J12<$G$8),J12,"") -> 822 | M12: 2397.5 | N12: 169.5 | P12: 40553 | Q12: 1321
I13: =P12 -> 40553 | J13: =Q12 -> 1321 | K13: =IF(OR(J13<$G$7,J13>$G$8),J13,"") | L13: =IF(AND(J13>$G$7,J13<$G$8),J13,"") -> 1321 | M13: 2397.5 | N13: 169.5 | P13: 40554 | Q13: 1263
I14: =P13 -> 40554 | J14: =Q13 -> 1263 | K14: =IF(OR(J14<$G$7,J14>$G$8),J14,"") | L14: =IF(AND(J14>$G$7,J14<$G$8),J14,"") -> 1263 | M14: 2397.5 | N14: 169.5 | P14: 40555 | Q14: 1162
I15: =P14 -> 40555 | J15: =Q14 -> 1162 | K15: =IF(OR(J15<$G$7,J15>$G$8),J15,"") | L15: =IF(AND(J15>$G$7,J15<$G$8),J15,"") -> 1162 | M15: 2397.5 | N15: 169.5 | P15: 40556 | Q15: 1406
I16: =P15 -> 40556 | J16: =Q15 -> 1406 | K16: =IF(OR(J16<$G$7,J16>$G$8),J16,"") | L16: =IF(AND(J16>$G$7,J16<$G$8),J16,"") -> 1406 | M16: 2397.5 | N16: 169.5 | P16: 40557 | Q16: 1421
I17: =P16 -> 40557 | J17: =Q16 -> 1421 | K17: =IF(OR(J17<$G$7,J17>$G$8),J17,"") | L17: =IF(AND(J17>$G$7,J17<$G$8),J17,"") -> 1421 | M17: 2397.5 | N17: 169.5 | P17: 40558 | Q17: 1248
I18: =P17 -> 40558 | J18: =Q17 -> 1248 | K18: =IF(OR(J18<$G$7,J18>$G$8),J18,"") | L18: =IF(AND(J18>$G$7,J18<$G$8),J18,"") -> 1248 | M18: 2397.5 | N18: 169.5 | P18: 40559 | Q18: 1204
I19: =P18 -> 40559 | J19: =Q18 -> 1204 | K19: =IF(OR(J19<$G$7,J19>$G$8),J19,"") | L19: =IF(AND(J19>$G$7,J19<$G$8),J19,"") -> 1204 | M19: 2397.5 | N19: 169.5 | P19: 40560 | Q19: 1000
I20: =P19 -> 40560 | J20: =Q19 -> 1000 | K20: =IF(OR(J20<$G$7,J20>$G$8),J20,"") | L20: =IF(AND(J20>$G$7,J20<$G$8),J20,"") -> 1000 | M20: 2397.5 | N20: 169.5 | P20: 40561 | Q20: 683
... I47: =P46 -> 40587 | J47: =Q46 -> 1589 | K47: =IF(OR(J47<$G$7,J47>$G$8),J47,"") | L47: =IF(AND(J47>$G$7,J47<$G$8),J47,"") -> 1589 | M47: 2397.5 | N47: 169.5 | P47: 40588 | Q47: 151
I48: =P47 -> 40588 | J48: =Q47 -> 151 | K48: =IF(OR(J48<$G$7,J48>$G$8),J48,"") -> 151 | M48: 2397.5 | N48: 169.5 | P48: Grand Total | Q48: 58304

Sheet Demand forecast
A1: Demand Forecast | B1: Rider Count | C1: Forecast(Rider Count) | D1: Lower Confidence Bound(Rider Count) | E1: Upper Confidence Bound(Rider Count)
A2: 46054 | B2: 1360
A3: 46055 | B3: 1526
A4: 46056 | B4: 1550
A5: 46057 | B5: 1708
A6: 46058 | B6: 1005
A7: 46059 | B7: 1623
A8: 46060 | B8: 1712
A9: 46061 | B9: 1530
A10: 46062 | B10: 1605
A11: 46063 | B11: 1538
A12: 46064 | B12: 1746
A13: 46065 | B13: 1472
A14: 46066 | B14: 1589
A15: 46067 | B15: 151 | C15: 151 | D15: =C15-_xlfn.FORECAST.ETS.CONFINT(A15,$B$2:$B$15,$A$2:$A$15,0.95,1,1) -> #NUM! | E15: 151
A16: 46068 | C16: =_xlfn.FORECAST.ETS(A16,$B$2:$B$15,$A$2:$A$15,1,1) -> 1105.539 | D16: =MAX(0,C16-_xlfn.FORECAST.ETS.CONFINT(A16,$B$2:$B$15,$A$2:$A$15,0.95,1,1)) -> 276.77281 | E16: =C16+_xlfn.FORECAST.ETS.CONFINT(A16,$B$2:$B$15,$A$2:$A$15,0.95,1,1) -> 1934.3052
A17: 46069 | C17: =_xlfn.FORECAST.ETS(A17,$B$2:$B$15,$A$2:$A$15,1,1) -> 1077.4338 | D17: =MAX(0,C17-_xlfn.FORECAST.ETS.CONFINT(A17,$B$2:$B$15,$A$2:$A$15,0.95,1,1)) -> 222.95983 | E17: =C17+_xlfn.FORECAST.ETS.CONFINT(A17,$B$2:$B$15,$A$2:$A$15,0.95,1,1) -> 1931.9078
A18: 46070 | C18: =_xlfn.FORECAST.ETS(A18,$B$2:$B$15,$A$2:$A$15,1,1) -> 1049.3287 | D18: =MAX(0,C18-_xlfn.FORECAST.ETS.CONFINT(A18,$B$2:$B$15,$A$2:$A$15,0.95,1,1)) -> 169.70163 | E18: =C18+_xlfn.FORECAST.ETS.CONFINT(A18,$B$2:$B$15,$A$2:$A$15,0.95,1,1) -> 1928.9558
A19: 46071 | C19: =_xlfn.FORECAST.ETS(A19,$B$2:$B$15,$A$2:$A$15,1,1) -> 1021.2235 | D19: =MAX(0,C19-_xlfn.FORECAST.ETS.CONFINT(A19,$B$2:$B$15,$A$2:$A$15,0.95,1,1)) -> 116.95115 | E19: =C19+_xlfn.FORECAST.ETS.CONFINT(A19,$B$2:$B$15,$A$2:$A$15,0.95,1,1) -> 1925.4959
A20: 46072 | C20: =_xlfn.FORECAST.ETS(A20,$B$2:$B$15,$A$2:$A$15,1,1) -> 993.1184 | D20: =MAX(0,C20-_xlfn.FORECAST.ETS.CONFINT(A20,$B$2:$B$15,$A$2:$A$15,0.95,1,1)) -> 64.667214 | E20: =C20+_xlfn.FORECAST.ETS.CONFINT(A20,$B$2:$B$15,$A$2:$A$15,0.95,1,1) -> 1921.5696
A21: 46073 | C21: =_xlfn.FORECAST.ETS(A21,$B$2:$B$15,$A$2:$A$15,1,1) -> 965.01325 | D21: =MAX(0,C21-_xlfn.FORECAST.ETS.CONFINT(A21,$B$2:$B$15,$A$2:$A$15,0.95,1,1)) -> 12.813564 | E21: =C21+_xlfn.FORECAST.ETS.CONFINT(A21,$B$2:$B$15,$A$2:$A$15,0.95,1,1) -> 1917.2129
A22: 46074 | C22: =_xlfn.FORECAST.ETS(A22,$B$2:$B$15,$A$2:$A$15,1,1) -> 936.9081 | D22: =MAX(0,C22-_xlfn.FORECAST.ETS.CONFINT(A22,$B$2:$B$15,$A$2:$A$15,0.95,1,1)) -> 0 | E22: =C22+_xlfn.FORECAST.ETS.CONFINT(A22,$B$2:$B$15,$A$2:$A$15,0.95,1,1) -> 1912.4581
A23: 46075 | C23: =_xlfn.FORECAST.ETS(A23,$B$2:$B$15,$A$2:$A$15,1,1) -> 908.80295 | D23: =MAX(0,C23-_xlfn.FORECAST.ETS.CONFINT(A23,$B$2:$B$15,$A$2:$A$15,0.95,1,1)) -> 0 | E23: =C23+_xlfn.FORECAST.ETS.CONFINT(A23,$B$2:$B$15,$A$2:$A$15,0.95,1,1) -> 1907.3338
A24: 46076 | C24: =_xlfn.FORECAST.ETS(A24,$B$2:$B$15,$A$2:$A$15,1,1) -> 880.69781 | D24: =MAX(0,C24-_xlfn.FORECAST.ETS.CONFINT(A24,$B$2:$B$15,$A$2:$A$15,0.95,1,1)) -> 0 | E24: =C24+_xlfn.FORECAST.ETS.CONFINT(A24,$B$2:$B$15,$A$2:$A$15,0.95,1,1) -> 1901.8655
A25: 46077 | C25: =_xlfn.FORECAST.ETS(A25,$B$2:$B$15,$A$2:$A$15,1,1) -> 852.59266 | D25: =MAX(0,C25-_xlfn.FORECAST.ETS.CONFINT(A25,$B$2:$B$15,$A$2:$A$15,0.95,1,1)) -> 0 | E25: =C25+_xlfn.FORECAST.ETS.CONFINT(A25,$B$2:$B$15,$A$2:$A$15,0.95,1,1) -> 1896.0764
A26: 46078 | C26: =_xlfn.FORECAST.ETS(A26,$B$2:$B$15,$A$2:$A$15,1,1) -> 824.48751 | D26: =MAX(0,C26-_xlfn.FORECAST.ETS.CONFINT(A26,$B$2:$B$15,$A$2:$A$15,0.95,1,1)) -> 0 | E26: =C26+_xlfn.FORECAST.ETS.CONFINT(A26,$B$2:$B$15,$A$2:$A$15,0.95,1,1) -> 1889.9872
A27: 46079 | C27: =_xlfn.FORECAST.ETS(A27,$B$2:$B$15,$A$2:$A$15,1,1) -> 796.38236 | D27: =MAX(0,C27-_xlfn.FORECAST.ETS.CONFINT(A27,$B$2:$B$15,$A$2:$A$15,0.95,1,1)) -> 0 | E27: =C27+_xlfn.FORECAST.ETS.CONFINT(A27,$B$2:$B$15,$A$2:$A$15,0.95,1,1) -> 1883.6168
... A29: 46081 | C29: =_xlfn.FORECAST.ETS(A29,$B$2:$B$15,$A$2:$A$15,1,1) -> 740.17207 | D29: =MAX(0,C29-_xlfn.FORECAST.ETS.CONFINT(A29,$B$2:$B$15,$A$2:$A$15,0.95,1,1)) -> 0 | E29: =C29+_xlfn.FORECAST.ETS.CONFINT(A29,$B$2:$B$15,$A$2:$A$15,0.95,1,1) -> 1870.0996

Sheet pivot
A2: 1) Riders daily trend | D2: 2)Demand by weather | F2: Row Labels | G2: Sum of Total Count | I2: Q1 | J2: =_xlfn.QUARTILE.INC(G2:G25,1) -> 762.5 | AB2: Chart data | AK2: Chart Data
F3: 1 AM | G3: 460 | I3: Q3 | J3: =_xlfn.QUARTILE.INC(G3:G26,3) -> 3447.25 | P3: Row Labels | Q3: Sum of Casual Riders | R3: Sum of Registered Riders | T3: Rider | U3: Count | W3: Row Labels | X3: Sum of Humidity(%) | Y3: Sum of Total Count | AA3: Correlation | AB3: Humidity | AC3: Count | AF3: Row Labels | AG3: Sum of Temperature© | AH3: Sum of Total Count | AJ3: correlation | AK3: Humidity | AL3: Count
A4: Row Labels | B4: Sum of Total Count | D4: Row Labels | E4: Sum of Total Count | F4: 1 PM | G4: 3376 | K4: Hours | L4: High | M4: Moderate | N4: Low | P4: 1 | Q4: 3 | R4: 13 | T4: Casual | U4: =SUM(Q4:Q1003) -> 4921 | W4: 1 | X4: 0.81 | Y4: 16 | AA4: =CORREL(X4:X1003,Y4:Y1003) -> -0.2543533 | AB4: =X4 -> 0.81 | AC4: =Y4 -> 16 | AF4: 1 | AG4: 24 | AH4: 16 | AJ4: =CORREL(AK4:AK1003,AL4:AL1003) -> 0.22929155 | AK4: =AG4 -> 24 | AL4: =AH4 -> 16
A5: 01-Jan | B5: 985 | D5: Clear | E5: 37373 | F5: 10 AM | G5: 2253 | K5: 12 AM | M5: =IF(AND(G3<$J$3,G3>$J$2),G3,"") | N5: =IF(G3<$J$2,G3,"") -> 460 | P5: 2 | Q5: 8 | R5: 32 | T5: Registered | U5: =SUM(R4:R1003) -> 53383 | W5: 2 | X5: 0.8 | Y5: 40 | AB5: =X5 -> 0.8 | AC5: =Y5 -> 40 | AF5: 2 | AG5: 22 | AH5: 40 | AK5: =AG5 -> 22 | AL5: =AH5 -> 40
A6: 02-Jan | B6: 801 | D6: Mist | E6: 18106 | F6: 10 PM | G6: 1508 | K6: 1 AM | L6: =IF(G4>$J$3,G4,"") | M6: =IF(AND(G4<$J$3,G4>$J$2),G4,"") -> 3376 | N6: =IF(G4<$J$2,G4,"") | P6: 3 | Q6: 5 | R6: 27 | T6: Total | U6: =SUM(U4:U5) -> 58304 | W6: 3 | X6: 0.8 | Y6: 32 | AB6: =X6 -> 0.8 | AC6: =Y6 -> 32 | AF6: 3 | AG6: 22 | AH6: 32 | AK6: =AG6 -> 22 | AL6: =AH6 -> 32
A7: 03-Jan | B7: 1349 | D7: Rain | E7: 2789 | F7: 11 AM | G7: 2494 | K7: 2 AM | L7: =IF(G5>$J$3,G5,"") | M7: =IF(AND(G5<$J$3,G5>$J$2),G5,"") -> 2253 | N7: =IF(G5<$J$2,G5,"") | P7: 4 | Q7: 3 | R7: 10 | W7: 4 | X7: 0.75 | Y7: 13 | AB7: =X7 -> 0.75 | AC7: =Y7 -> 13 | AF7: 4 | AG7: 24 | AH7: 13 | AK7: =AG7 -> 24 | AL7: =AH7 -> 13
A8: 04-Jan | B8: 1562 | D8: Storm | E8: 36 | F8: 11 PM | G8: 1083 | K8: 3 AM | L8: =IF(G6>$J$3,G6,"") | M8: =IF(AND(G6<$J$3,G6>$J$2),G6,"") -> 1508 | N8: =IF(G6<$J$2,G6,"") | P8: 5 | Q8: 0 | R8: 1 | W8: 5 | X8: 0.75 | Y8: 1 | AB8: =X8 -> 0.75 | AC8: =Y8 -> 1 | AF8: 5 | AG8: 24 | AH8: 1 | AK8: =AG8 -> 24 | AL8: =AH8 -> 1
A9: 05-Jan | B9: 1600 | D9: Grand Total | E9: 58304 | F9: 12 AM | G9: 703 | K9: 4 AM | L9: =IF(G7>$J$3,G7,"") | M9: =IF(AND(G7<$J$3,G7>$J$2),G7,"") -> 2494 | N9: =IF(G7<$J$2,G7,"") | P9: 6 | Q9: 0 | R9: 1 | W9: 6 | X9: 0.75 | Y9: 1 | AB9: =X9 -> 0.75 | AC9: =Y9 -> 1 | AF9: 6 | AG9: 24 | AH9: 1 | AK9: =AG9 -> 24 | AL9: =AH9 -> 1
A10: 06-Jan | B10: 1606 | F10: 12 PM | G10: 3283 | K10: 5 AM | L10: =IF(G8>$J$3,G8,"") | M10: =IF(AND(G8<$J$3,G8>$J$2),G8,"") -> 1083 | N10: =IF(G8<$J$2,G8,"") | P10: 7 | Q10: 2 | R10: 0 | W10: 7 | X10: 0.8 | Y10: 2 | AB10: =X10 -> 0.8 | AC10: =Y10 -> 2 | AF10: 7 | AG10: 22 | AH10: 2 | AK10: =AG10 -> 22 | AL10: =AH10 -> 2
A11: 07-Jan | B11: 1510 | F11: 2 AM | G11: 294 | K11: 6 AM | L11: =IF(G9>$J$3,G9,"") | M11: =IF(AND(G9<$J$3,G9>$J$2),G9,"") | N11: =IF(G9<$J$2,G9,"") -> 703 | P11: 8 | Q11: 1 | R11: 2 | W11: 8 | X11: 0.86 | Y11: 3 | AB11: =X11 -> 0.86 | AC11: =Y11 -> 3 | AF11: 8 | AG11: 20 | AH11: 3 | AK11: =AG11 -> 20 | AL11: =AH11 -> 3
A12: 08-Jan | B12: 959 | F12: 2 PM | G12: 3200 | K12: 7 AM | L12: =IF(G10>$J$3,G10,"") | M12: =IF(AND(G10<$J$3,G10>$J$2),G10,"") -> 3283 | N12: =IF(G10<$J$2,G10,"") | P12: 9 | Q12: 1 | R12: 7 | W12: 9 | X12: 0.75 | Y12: 8 | AB12: =X12 -> 0.75 | AC12: =Y12 -> 8 | AF12: 9 | AG12: 24 | AH12: 8 | AK12: =AG12 -> 24 | AL12: =AH12 -> 8
A13: 09-Jan | B13: 822 | F13: 3 AM | G13: 151 | K13: 8 AM | L13: =IF(G11>$J$3,G11,"") | M13: =IF(AND(G11<$J$3,G11>$J$2),G11,"") | N13: =IF(G11<$J$2,G11,"") -> 294 | P13: 10 | Q13: 8 | R13: 6 | W13: 10 | X13: 0.76 | Y13: 14 | AB13: =X13 -> 0.76 | AC13: =Y13 -> 14 | AF13: 10 | AG13: 32 | AH13: 14 | AK13: =AG13 -> 32 | AL13: =AH13 -> 14
A14: 10-Jan | B14: 1321 | F14: 3 PM | G14: 3352 | K14: 9 AM | L14: =IF(G12>$J$3,G12,"") | M14: =IF(AND(G12<$J$3,G12>$J$2),G12,"") -> 3200 | N14: =IF(G12<$J$2,G12,"") | P14: 11 | Q14: 12 | R14: 24 | W14: 11 | X14: 0.76 | Y14: 36 | AB14: =X14 -> 0.76 | AC14: =Y14 -> 36 | AF14: 11 | AG14: 38 | AH14: 36 | AK14: =AG14 -> 38 | AL14: =AH14 -> 36
A15: 11-Jan | B15: 1263 | F15: 4 AM | G15: 69 | K15: 10 AM | L15: =IF(G13>$J$3,G13,"") | M15: =IF(AND(G13<$J$3,G13>$J$2),G13,"") | N15: =IF(G13<$J$2,G13,"") -> 151 | P15: 12 | Q15: 26 | R15: 30 | W15: 12 | X15: 0.81 | Y15: 56 | AB15: =X15 -> 0.81 | AC15: =Y15 -> 56 | AF15: 12 | AG15: 36 | AH15: 56 | AK15: =AG15 -> 36 | AL15: =AH15 -> 56
A16: 12-Jan | B16: 1162 | F16: 4 PM | G16: 3928 | K16: 11 AM | L16: =IF(G14>$J$3,G14,"") | M16: =IF(AND(G14<$J$3,G14>$J$2),G14,"") -> 3352 | N16: =IF(G14<$J$2,G14,"") | P16: 13 | Q16: 29 | R16: 55 | W16: 13 | X16: 0.77 | Y16: 84 | AB16: =X16 -> 0.77 | AC16: =Y16 -> 84 | AF16: 13 | AG16: 42 | AH16: 84 | AK16: =AG16 -> 42 | AL16: =AH16 -> 84
A17: 13-Jan | B17: 1406 | F17: 5 AM | G17: 164 | K17: 12 PM | L17: =IF(G15>$J$3,G15,"") | M17: =IF(AND(G15<$J$3,G15>$J$2),G15,"") | N17: =IF(G15<$J$2,G15,"") -> 69 | P17: 14 | Q17: 47 | R17: 47 | T17: Row Labels | U17: Sum of Total Count | W17: 14 | X17: 0.72 | Y17: 94 | AB17: =X17 -> 0.72 | AC17: =Y17 -> 94 | AF17: 14 | AG17: 46 | AH17: 94 | AK17: =AG17 -> 46 | AL17: =AH17 -> 94
A18: 14-Jan | B18: 1421 | F18: 5 PM | G18: 6169 | K18: 1 PM | L18: =IF(G16>$J$3,G16,"") -> 3928 | M18: =IF(AND(G16<$J$3,G16>$J$2),G16,"") | N18: =IF(G16<$J$2,G16,"") | P18: 15 | Q18: 35 | R18: 71 | T18: 2-12 | U18: 0.047663968 | W18: 15 | X18: 0.72 | Y18: 106 | AB18: =X18 -> 0.72 | AC18: =Y18 -> 106 | AF18: 15 | AG18: 46 | AH18: 106 | AK18: =AG18 -> 46 | AL18: =AH18 -> 106
A19: 15-Jan | B19: 1248 | F19: 6 AM | G19: 822 | K19: 2 PM | L19: =IF(G17>$J$3,G17,"") | M19: =IF(AND(G17<$J$3,G17>$J$2),G17,"") | N19: =IF(G17<$J$2,G17,"") -> 164 | P19: 16 | Q19: 40 | R19: 70 | T19: 12-22 | U19: 0.43587061 | W19: 16 | X19: 0.77 | Y19: 110 | AB19: =X19 -> 0.77 | AC19: =Y19 -> 110 | AF19: 16 | AG19: 44 | AH19: 110 | AK19: =AG19 -> 44 | AL19: =AH19 -> 110
A20: 16-Jan | B20: 1204 | F20: 6 PM | G20: 5283 | K20: 3 PM | L20: =IF(G18>$J$3,G18,"") -> 6169 | M20: =IF(AND(G18<$J$3,G18>$J$2),G18,"") | N20: =IF(G18<$J$2,G18,"") | P20: 17 | Q20: 41 | R20: 52 | T20: 22-32 | U20: 0.37463982 | W20: 17 | X20: 0.82 | Y20: 93 | AB20: =X20 -> 0.82 | AC20: =Y20 -> 93 | AF20: 17 | AG20: 42 | AH20: 93 | AK20: =AG20 -> 42 | AL20: =AH20 -> 93
A21: 17-Jan | B21: 1000 | F21: 7 AM | G21: 2339 | K21: 4 PM | L21: =IF(G19>$J$3,G19,"") | M21: =IF(AND(G19<$J$3,G19>$J$2),G19,"") -> 822 | N21: =IF(G19<$J$2,G19,"") | P21: 18 | Q21: 15 | R21: 52 | T21: 32-42 | U21: 0.12505145 | W21: 18 | X21: 0.82 | Y21: 67 | AB21: =X21 -> 0.82 | AC21: =Y21 -> 67 | AF21: 18 | AG21: 44 | AH21: 67 | AK21: =AG21 -> 44 | AL21: =AH21 -> 67
A22: 18-Jan | B22: 683 | F22: 7 PM | G22: 3661 | K22: 5 PM | L22: =IF(G20>$J$3,G20,"") -> 5283 | M22: =IF(AND(G20<$J$3,G20>$J$2),G20,"") | N22: =IF(G20<$J$2,G20,"") | P22: 19 | Q22: 9 | R22: 26 | T22: 42-52 | U22: 0.016774149 | W22: 19 | X22: 0.88 | Y22: 35 | AB22: =X22 -> 0.88 | AC22: =Y22 -> 35 | AF22: 19 | AG22: 42 | AH22: 35 | AK22: =AG22 -> 42 | AL22: =AH22 -> 35
A23: 19-Jan | B23: 1650 | F23: 8 AM | G23: 5388 | K23: 6 PM | L23: =IF(G21>$J$3,G21,"") | M23: =IF(AND(G21<$J$3,G21>$J$2),G21,"") -> 2339 | N23: =IF(G21<$J$2,G21,"") | P23: 20 | Q23: 6 | R23: 31 | T23: Grand Total | U23: 1 | W23: 20 | X23: 0.88 | Y23: 37 | AB23: =X23 -> 0.88 | AC23: =Y23 -> 37 | AF23: 20 | AG23: 42 | AH23: 37 | AK23: =AG23 -> 42 | AL23: =AH23 -> 37
A24: 20-Jan | B24: 1927 | F24: 8 PM | G24: 2656 | K24: 7 PM | L24: =IF(G22>$J$3,G22,"") -> 3661 | M24: =IF(AND(G22<$J$3,G22>$J$2),G22,"") | N24: =IF(G22<$J$2,G22,"") | P24: 21 | Q24: 11 | R24: 25 | W24: 21 | X24: 0.87 | Y24: 36 | AB24: =X24 -> 0.87 | AC24: =Y24 -> 36 | AF24: 21 | AG24: 40 | AH24: 36 | AK24: =AG24 -> 40 | AL24: =AH24 -> 36
A25: 21-Jan | B25: 1543 | F25: 9 AM | G25: 3672 | K25: 8 PM | L25: =IF(G23>$J$3,G23,"") -> 5388 | M25: =IF(AND(G23<$J$3,G23>$J$2),G23,"") | N25: =IF(G23<$J$2,G23,"") | P25: 22 | Q25: 3 | R25: 31 | W25: 22 | X25: 0.87 | Y25: 34 | AB25: =X25 -> 0.87 | AC25: =Y25 -> 34 | AF25: 22 | AG25: 40 | AH25: 34 | AK25: =AG25 -> 40 | AL25: =AH25 -> 34
A26: 22-Jan | B26: 981 | F26: 9 PM | G26: 1996 | K26: 9 PM | L26: =IF(G24>$J$3,G24,"") | M26: =IF(AND(G24<$J$3,G24>$J$2),G24,"") -> 2656 | N26: =IF(G24<$J$2,G24,"") | P26: 23 | Q26: 11 | R26: 17 | W26: 23 | X26: 0.94 | Y26: 28 | AB26: =X26 -> 0.94 | AC26: =Y26 -> 28 | AF26: 23 | AG26: 40 | AH26: 28 | AK26: =AG26 -> 40 | AL26: =AH26 -> 28
A27: 23-Jan | B27: 986 | F27: Grand Total | G27: 58304 | K27: 10 PM | L27: =IF(G25>$J$3,G25,"") -> 3672 | M27: =IF(AND(G25<$J$3,G25>$J$2),G25,"") | N27: =IF(G25<$J$2,G25,"") | P27: 24 | Q27: 15 | R27: 24 | W27: 24 | X27: 0.88 | Y27: 39 | AB27: =X27 -> 0.88 | AC27: =Y27 -> 39 | AF27: 24 | AG27: 46 | AH27: 39 | AK27: =AG27 -> 46 | AL27: =AH27 -> 39
A28: 24-Jan | B28: 1416 | K28: 11 PM | L28: =IF(G26>$J$3,G26,"") | M28: =IF(AND(G26<$J$3,G26>$J$2),G26,"") -> 1996 | N28: =IF(G26<$J$2,G26,"") | P28: 25 | Q28: 4 | R28: 13 | W28: 25 | X28: 0.88 | Y28: 17 | AB28: =X28 -> 0.88 | AC28: =Y28 -> 17 | AF28: 25 | AG28: 46 | AH28: 17 | AK28: =AG28 -> 46 | AL28: =AH28 -> 17
A29: 25-Jan | B29: 1985 | P29: 26 | Q29: 1 | R29: 16 | W29: 26 | X29: 0.94 | Y29: 17 | AB29: =X29 -> 0.94 | AC29: =Y29 -> 17 | AF29: 26 | AG29: 44 | AH29: 17 | AK29: =AG29 -> 44 | AL29: =AH29 -> 17
A30: 26-Jan | B30: 506 | P30: 27 | Q30: 1 | R30: 8 | W30: 27 | X30: 1 | Y30: 9 | AB30: =X30 -> 1 | AC30: =Y30 -> 9 | AF30: 27 | AG30: 42 | AH30: 9 | AK30: =AG30 -> 42 | AL30: =AH30 -> 9
A31: 27-Jan | B31: 431 | H31: 1232 | P31: 28 | Q31: 2 | R31: 4 | W31: 28 | X31: 0.94 | Y31: 6 | AB31: =X31 -> 0.94 | AC31: =Y31 -> 6 | AF31: 28 | AG31: 46 | AH31: 6 | AK31: =AG31 -> 46 | AL31: =AH31 -> 6
A32: 28-Jan | B32: 1167 | H32: 1437 | I32: =H32-H31 -> 205 | P32: 29 | Q32: 2 | R32: 1 | W32: 29 | X32: 0.94 | Y32: 3 | AB32: =X32 -> 0.94 | AC32: =Y32 -> 3 | AF32: 29 | AG32: 46 | AH32: 3 | AK32: =AG32 -> 46 | AL32: =AH32 -> 3
A33: 29-Jan | B33: 1098 | D33: Demand Forecast | E33: Rider Count | P33: 30 | Q33: 0 | R33: 2 | W33: 30 | X33: 0.77 | Y33: 2 | AB33: =X33 -> 0.77 | AC33: =Y33 -> 2 | AF33: 30 | AG33: 42 | AH33: 2 | AK33: =AG33 -> 42 | AL33: =AH33 -> 2
A34: 30-Jan | B34: 1096 | D34: 46054 | E34: =B36 -> 1360 | P34: 31 | Q34: 0 | R34: 1 | W34: 31 | X34: 0.76 | Y34: 1 | AB34: =X34 -> 0.76 | AC34: =Y34 -> 1 | AF34: 31 | AG34: 40 | AH34: 1 | AK34: =AG34 -> 40 | AL34: =AH34 -> 1
A35: 31-Jan | B35: 1501 | D35: 46055 | E35: =B37 -> 1526 | P35: 32 | Q35: 0 | R35: 8 | W35: 32 | X35: 0.71 | Y35: 8 | AB35: =X35 -> 0.71 | AC35: =Y35 -> 8 | AF35: 32 | AG35: 40 | AH35: 8 | AK35: =AG35 -> 40 | AL35: =AH35 -> 8
A36: 01-Feb | B36: 1360 | D36: 46056 | E36: =B38 -> 1550 | P36: 33 | Q36: 1 | R36: 19 | W36: 33 | X36: 0.76 | Y36: 20 | AB36: =X36 -> 0.76 | AC36: =Y36 -> 20 | AF36: 33 | AG36: 38 | AH36: 20 | AK36: =AG36 -> 38 | AL36: =AH36 -> 20
A37: 02-Feb | B37: 1526 | D37: 46057 | E37: =B39 -> 1708 | P37: 34 | Q37: 7 | R37: 46 | W37: 34 | X37: 0.81 | Y37: 53 | AB37: =X37 -> 0.81 | AC37: =Y37 -> 53 | AF37: 34 | AG37: 36 | AH37: 53 | AK37: =AG37 -> 36 | AL37: =AH37 -> 53
A38: 03-Feb | B38: 1550 | D38: 46058 | E38: =B40 -> 1005 | P38: 35 | Q38: 16 | R38: 54 | W38: 35 | X38: 0.71 | Y38: 70 | AB38: =X38 -> 0.71 | AC38: =Y38 -> 70 | AF38: 35 | AG38: 36 | AH38: 70 | AK38: =AG38 -> 36 | AL38: =AH38 -> 70
A39: 04-Feb | B39: 1708 | D39: 46059 | E39: =B41 -> 1623 | P39: 36 | Q39: 20 | R39: 73 | W39: 36 | X39: 0.66 | Y39: 93 | AB39: =X39 -> 0.66 | AC39: =Y39 -> 93 | AF39: 36 | AG39: 36 | AH39: 93 | AK39: =AG39 -> 36 | AL39: =AH39 -> 93
A40: 05-Feb | B40: 1005 | D40: 46060 | E40: =B42 -> 1712 | P40: 37 | Q40: 11 | R40: 64 | W40: 37 | X40: 0.66 | Y40: 75 | AB40: =X40 -> 0.66 | AC40: =Y40 -> 75 | AF40: 37 | AG40: 36 | AH40: 75 | AK40: =AG40 -> 36 | AL40: =AH40 -> 75
A41: 06-Feb | B41: 1623 | D41: 46061 | E41: =B43 -> 1530 | P41: 38 | Q41: 4 | R41: 55 | W41: 38 | X41: 0.76 | Y41: 59 | AB41: =X41 -> 0.76 | AC41: =Y41 -> 59 | AF41: 38 | AG41: 36 | AH41: 59 | AK41: =AG41 -> 36 | AL41: =AH41 -> 59
...

Sheet working data
A1: instant | B1: Date | C1: holiday | D1: Days | E1: atemp | F1: Year | G1: Month | H1: Hour | I1: Weekday/weekend | J1: Season | K1: Weather | L1: Humidity(%) | M1: windspeed (%) | N1: Temperature© | O1: Casual Riders | P1: Registered Riders | Q1: Total Count | R1: Demand | S1: Count outliners | T1: humidity outliners | U1: Windspeed outliners
A2: 1 | B2: 40544 | C2: FALSE | D2: =TEXT(B2,"dddd") -> Saturday | E2: 0.2879 | F2: =YEAR('Merged raw data'!$B2) -> 2011 | G2: =TEXT('Merged raw data'!$B2,"mmmm") -> January | H2: =TEXT(TIME('Merged raw data'!F2,0,0),"h AM/PM") -> 12 AM | I2: =IF(OR('Merged raw data'!H2=1,'Merged raw data'!H2=2,'Merged raw data'!H2=3,'Merged raw data'!H2=4,'Merged raw data'!H2=5),"weekday","weekend") -> weekend | J2: Spring | K2: =IF('Merged raw data'!I2=1,"Clear",IF('Merged raw data'!I2=2,"Mist",IF('Merged raw data'!I2=3,"Rain",IF('Merged raw data'!I2=4,"Storm","NA")))) -> Clear | L2: 0.81 | M2: 0.23 | N2: ='Merged raw data'!$J2*100 -> 24 | O2: 3 | P2: 13 | Q2: 16 | R2: =IF(Q2>=outliers!I4,"High",IF(Q2<=outliers!I3,"Low","Moderate")) -> Low | S2: =IF(OR(Q2<outliers!$I$6,Q2>outliers!$I$7),"Outlier","Normal") -> Normal | T2: =IF(OR(L2<outliers!$J$6,L2>outliers!$J$7),"Outlier","Normal") -> Normal | U2: =IF(OR(M2<outliers!$K$6,M2>outliers!$K$7),"Outlier","Normal") -> Normal
A3: 2 | B3: 40544 | C3: FALSE | D3: =TEXT(B3,"dddd") -> Saturday | E3: 0.2727 | F3: =YEAR('Merged raw data'!$B3) -> 2011 | G3: =TEXT('Merged raw data'!$B3,"mmmm") -> January | H3: =TEXT(TIME('Merged raw data'!F3,0,0),"h AM/PM") -> 1 AM | I3: =IF(OR('Merged raw data'!H3=1,'Merged raw data'!H3=2,'Merged raw data'!H3=3,'Merged raw data'!H3=4,'Merged raw data'!H3=5),"weekday","weekend") -> weekend | J3: Spring | K3: =IF('Merged raw data'!I3=1,"Clear",IF('Merged raw data'!I3=2,"Mist",IF('Merged raw data'!I3=3,"Rain",IF('Merged raw data'!I3=4,"Storm","NA")))) -> Clear | L3: 0.8 | M3: 0.23 | N3: ='Merged raw data'!$J3*100 -> 22 | O3: 8 | P3: 32 | Q3: 40 | R3: =IF(Q3>=outliers!I5,"High",IF(Q3<=outliers!I4,"Low","Moderate")) -> Low | S3: =IF(OR(Q3<outliers!$I$6,Q3>outliers!$I$7),"Outlier","Normal") -> Normal | T3: =IF(OR(L3<outliers!$J$6,L3>outliers!$J$7),"Outlier","Normal") -> Normal | U3: =IF(OR(M3<outliers!$K$6,M3>outliers!$K$7),"Outlier","Normal") -> Normal
A4: 3 | B4: 40544 | C4: FALSE | D4: =TEXT(B4,"dddd") -> Saturday | E4: 0.2727 | F4: =YEAR('Merged raw data'!$B4) -> 2011 | G4: =TEXT('Merged raw data'!$B4,"mmmm") -> January | H4: =TEXT(TIME('Merged raw data'!F4,0,0),"h AM/PM") -> 2 AM | I4: =IF(OR('Merged raw data'!H4=1,'Merged raw data'!H4=2,'Merged raw data'!H4=3,'Merged raw data'!H4=4,'Merged raw data'!H4=5),"weekday","weekend") -> weekend | J4: Spring | K4: =IF('Merged raw data'!I4=1,"Clear",IF('Merged raw data'!I4=2,"Mist",IF('Merged raw data'!I4=3,"Rain",IF('Merged raw data'!I4=4,"Storm","NA")))) -> Clear | L4: 0.8 | M4: 0.23 | N4: ='Merged raw data'!$J4*100 -> 22 | O4: 5 | P4: 27 | Q4: 32 | R4: =IF(Q4>=outliers!I6,"High",IF(Q4<=outliers!I5,"Low","Moderate")) -> High | S4: =IF(OR(Q4<outliers!$I$6,Q4>outliers!$I$7),"Outlier","Normal") -> Normal | T4: =IF(OR(L4<outliers!$J$6,L4>outliers!$J$7),"Outlier","Normal") -> Normal | U4: =IF(OR(M4<outliers!$K$6,M4>outliers!$K$7),"Outlier","Normal") -> Normal
A5: 4 | B5: 40544 | C5: FALSE | D5: =TEXT(B5,"dddd") -> Saturday | E5: 0.2879 | F5: =YEAR('Merged raw data'!$B5) -> 2011 | G5: =TEXT('Merged raw data'!$B5,"mmmm") -> January | H5: =TEXT(TIME('Merged raw data'!F5,0,0),"h AM/PM") -> 3 AM | I5: =IF(OR('Merged raw data'!H5=1,'Merged raw data'!H5=2,'Merged raw data'!H5=3,'Merged raw data'!H5=4,'Merged raw data'!H5=5),"weekday","weekend") -> weekend | J5: Spring | K5: =IF('Merged raw data'!I5=1,"Clear",IF('Merged raw data'!I5=2,"Mist",IF('Merged raw data'!I5=3,"Rain",IF('Merged raw data'!I5=4,"Storm","NA")))) -> Clear | L5: 0.75 | M5: 0.23 | N5: ='Merged raw data'!$J5*100 -> 24 | O5: 3 | P5: 10 | Q5: 13 | R5: =IF(Q5>=outliers!I7,"High",IF(Q5<=outliers!I6,"Low","Moderate")) -> Moderate | S5: =IF(OR(Q5<outliers!$I$6,Q5>outliers!$I$7),"Outlier","Normal") -> Normal | T5: =IF(OR(L5<outliers!$J$6,L5>outliers!$J$7),"Outlier","Normal") -> Normal | U5: =IF(OR(M5<outliers!$K$6,M5>outliers!$K$7),"Outlier","Normal") -> Normal
A6: 5 | B6: 40544 | C6: FALSE | D6: =TEXT(B6,"dddd") -> Saturday | E6: 0.2879 | F6: =YEAR('Merged raw data'!$B6) -> 2011 | G6: =TEXT('Merged raw data'!$B6,"mmmm") -> January | H6: =TEXT(TIME('Merged raw data'!F6,0,0),"h AM/PM") -> 4 AM | I6: =IF(OR('Merged raw data'!H6=1,'Merged raw data'!H6=2,'Merged raw data'!H6=3,'Merged raw data'!H6=4,'Merged raw data'!H6=5),"weekday","weekend") -> weekend | J6: Spring | K6: =IF('Merged raw data'!I6=1,"Clear",IF('Merged raw data'!I6=2,"Mist",IF('Merged raw data'!I6=3,"Rain",IF('Merged raw data'!I6=4,"Storm","NA")))) -> Clear | L6: 0.75 | M6: 0.23 | N6: ='Merged raw data'!$J6*100 -> 24 | O6: 0 | P6: 1 | Q6: 1 | R6: =IF(Q6>=outliers!I8,"High",IF(Q6<=outliers!I7,"Low","Moderate")) -> High | S6: =IF(OR(Q6<outliers!$I$6,Q6>outliers!$I$7),"Outlier","Normal") -> Normal | T6: =IF(OR(L6<outliers!$J$6,L6>outliers!$J$7),"Outlier","Normal") -> Normal | U6: =IF(OR(M6<outliers!$K$6,M6>outliers!$K$7),"Outlier","Normal") -> Normal
A7: 6 | B7: 40544 | C7: FALSE | D7: =TEXT(B7,"dddd") -> Saturday | E7: 0.2576 | F7: =YEAR('Merged raw data'!$B7) -> 2011 | G7: =TEXT('Merged raw data'!$B7,"mmmm") -> January | H7: =TEXT(TIME('Merged raw data'!F7,0,0),"h AM/PM") -> 5 AM | I7: =IF(OR('Merged raw data'!H7=1,'Merged raw data'!H7=2,'Merged raw data'!H7=3,'Merged raw data'!H7=4,'Merged raw data'!H7=5),"weekday","weekend") -> weekend | J7: Spring | K7: =IF('Merged raw data'!I7=1,"Clear",IF('Merged raw data'!I7=2,"Mist",IF('Merged raw data'!I7=3,"Rain",IF('Merged raw data'!I7=4,"Storm","NA")))) -> Mist | L7: 0.75 | M7: 0.0896 | N7: ='Merged raw data'!$J7*100 -> 24 | O7: 0 | P7: 1 | Q7: 1 | R7: =IF(Q7>=outliers!I9,"High",IF(Q7<=outliers!I8,"Low","Moderate")) -> High | S7: =IF(OR(Q7<outliers!$I$6,Q7>outliers!$I$7),"Outlier","Normal") -> Normal | T7: =IF(OR(L7<outliers!$J$6,L7>outliers!$J$7),"Outlier","Normal") -> Normal | U7: =IF(OR(M7<outliers!$K$6,M7>outliers!$K$7),"Outlier","Normal") -> Normal
A8: 7 | B8: 40544 | C8: FALSE | D8: =TEXT(B8,"dddd") -> Saturday | E8: 0.2727 | F8: =YEAR('Merged raw data'!$B8) -> 2011 | G8: =TEXT('Merged raw data'!$B8,"mmmm") -> January | H8: =TEXT(TIME('Merged raw data'!F8,0,0),"h AM/PM") -> 6 AM | I8: =IF(OR('Merged raw data'!H8=1,'Merged raw data'!H8=2,'Merged raw data'!H8=3,'Merged raw data'!H8=4,'Merged raw data'!H8=5),"weekday","weekend") -> weekend | J8: Spring | K8: =IF('Merged raw data'!I8=1,"Clear",IF('Merged raw data'!I8=2,"Mist",IF('Merged raw data'!I8=3,"Rain",IF('Merged raw data'!I8=4,"Storm","NA")))) -> Clear | L8: 0.8 | M8: 0.23 | N8: ='Merged raw data'!$J8*100 -> 22 | O8: 2 | P8: 0 | Q8: 2 | R8: =IF(Q8>=outliers!I10,"High",IF(Q8<=outliers!I9,"Low","Moderate")) -> High | S8: =IF(OR(Q8<outliers!$I$6,Q8>outliers!$I$7),"Outlier","Normal") -> Normal | T8: =IF(OR(L8<outliers!$J$6,L8>outliers!$J$7),"Outlier","Normal") -> Normal | U8: =IF(OR(M8<outliers!$K$6,M8>outliers!$K$7),"Outlier","Normal") -> Normal
A9: 8 | B9: 40544 | C9: FALSE | D9: =TEXT(B9,"dddd") -> Saturday | E9: 0.2576 | F9: =YEAR('Merged raw data'!$B9) -> 2011 | G9: =TEXT('Merged raw data'!$B9,"mmmm") -> January | H9: =TEXT(TIME('Merged raw data'!F9,0,0),"h AM/PM") -> 7 AM | I9: =IF(OR('Merged raw data'!H9=1,'Merged raw data'!H9=2,'Merged raw data'!H9=3,'Merged raw data'!H9=4,'Merged raw data'!H9=5),"weekday","weekend") -> weekend | J9: Spring | K9: =IF('Merged raw data'!I9=1,"Clear",IF('Merged raw data'!I9=2,"Mist",IF('Merged raw data'!I9=3,"Rain",IF('Merged raw data'!I9=4,"Storm","NA")))) -> Clear | L9: 0.86 | M9: 0.23 | N9: ='Merged raw data'!$J9*100 -> 20 | O9: 1 | P9: 2 | Q9: 3 | R9: =IF(Q9>=outliers!I11,"High",IF(Q9<=outliers!I10,"Low","Moderate")) -> High | S9: =IF(OR(Q9<outliers!$I$6,Q9>outliers!$I$7),"Outlier","Normal") -> Normal | T9: =IF(OR(L9<outliers!$J$6,L9>outliers!$J$7),"Outlier","Normal") -> Normal | U9: =IF(OR(M9<outliers!$K$6,M9>outliers!$K$7),"Outlier","Normal") -> Normal
A10: 9 | B10: 40544 | C10: FALSE | D10: =TEXT(B10,"dddd") -> Saturday | E10: 0.21 | F10: =YEAR('Merged raw data'!$B10) -> 2011 | G10: =TEXT('Merged raw data'!$B10,"mmmm") -> January | H10: =TEXT(TIME('Merged raw data'!F10,0,0),"h AM/PM") -> 8 AM | I10: =IF(OR('Merged raw data'!H10=1,'Merged raw data'!H10=2,'Merged raw data'!H10=3,'Merged raw data'!H10=4,'Merged raw data'!H10=5),"weekday","weekend") -> weekend | J10: Spring | K10: =IF('Merged raw data'!I10=1,"Clear",IF('Merged raw data'!I10=2,"Mist",IF('Merged raw data'!I10=3,"Rain",IF('Merged raw data'!I10=4,"Storm","NA")))) -> Clear | L10: 0.75 | M10: 0.23 | N10: ='Merged raw data'!$J10*100 -> 24 | O10: 1 | P10: 7 | Q10: 8 | R10: =IF(Q10>=outliers!I12,"High",IF(Q10<=outliers!I11,"Low","Moderate")) -> High | S10: =IF(OR(Q10<outliers!$I$6,Q10>outliers!$I$7),"Outlier","Normal") -> Normal | T10: =IF(OR(L10<outliers!$J$6,L10>outliers!$J$7),"Outlier","Normal") -> Normal | U10: =IF(OR(M10<outliers!$K$6,M10>outliers!$K$7),"Outlier","Normal") -> Normal
A11: 10 | B11: 40544 | C11: FALSE | D11: =TEXT(B11,"dddd") -> Saturday | E11: 0.3485 | F11: =YEAR('Merged raw data'!$B11) -> 2011 | G11: =TEXT('Merged raw data'!$B11,"mmmm") -> January | H11: =TEXT(TIME('Merged raw data'!F11,0,0),"h AM/PM") -> 9 AM | I11: =IF(OR('Merged raw data'!H11=1,'Merged raw data'!H11=2,'Merged raw data'!H11=3,'Merged raw data'!H11=4,'Merged raw data'!H11=5),"weekday","weekend") -> weekend | J11: Spring | K11: =IF('Merged raw data'!I11=1,"Clear",IF('Merged raw data'!I11=2,"Mist",IF('Merged raw data'!I11=3,"Rain",IF('Merged raw data'!I11=4,"Storm","NA")))) -> Clear | L11: 0.76 | M11: 0.23 | N11: ='Merged raw data'!$J11*100 -> 32 | O11: 8 | P11: 6 | Q11: 14 | R11: =IF(Q11>=outliers!I13,"High",IF(Q11<=outliers!I12,"Low","Moderate")) -> High | S11: =IF(OR(Q11<outliers!$I$6,Q11>outliers!$I$7),"Outlier","Normal") -> Normal | T11: =IF(OR(L11<outliers!$J$6,L11>outliers!$J$7),"Outlier","Normal") -> Normal | U11: =IF(OR(M11<outliers!$K$6,M11>outliers!$K$7),"Outlier","Normal") -> Normal
A12: 11 | B12: 40544 | C12: FALSE | D12: =TEXT(B12,"dddd") -> Saturday | E12: 0.3939 | F12: =YEAR('Merged raw data'!$B12) -> 2011 | G12: =TEXT('Merged raw data'!$B12,"mmmm") -> January | H12: =TEXT(TIME('Merged raw data'!F12,0,0),"h AM/PM") -> 10 AM | I12: =IF(OR('Merged raw data'!H12=1,'Merged raw data'!H12=2,'Merged raw data'!H12=3,'Merged raw data'!H12=4,'Merged raw data'!H12=5),"weekday","weekend") -> weekend | J12: Spring | K12: =IF('Merged raw data'!I12=1,"Clear",IF('Merged raw data'!I12=2,"Mist",IF('Merged raw data'!I12=3,"Rain",IF('Merged raw data'!I12=4,"Storm","NA")))) -> Clear | L12: 0.76 | M12: 0.2537 | N12: ='Merged raw data'!$J12*100 -> 38 | O12: 12 | P12: 24 | Q12: 36 | R12: =IF(Q12>=outliers!I14,"High",IF(Q12<=outliers!I13,"Low","Moderate")) -> High | S12: =IF(OR(Q12<outliers!$I$6,Q12>outliers!$I$7),"Outlier","Normal") -> Normal | T12: =IF(OR(L12<outliers!$J$6,L12>outliers!$J$7),"Outlier","Normal") -> Normal | U12: =IF(OR(M12<outliers!$K$6,M12>outliers!$K$7),"Outlier","Normal") -> Normal
A13: 12 | B13: 40544 | C13: FALSE | D13: =TEXT(B13,"dddd") -> Saturday | E13: 0.3333 | F13: =YEAR('Merged raw data'!$B13) -> 2011 | G13: =TEXT('Merged raw data'!$B13,"mmmm") -> January | H13: =TEXT(TIME('Merged raw data'!F13,0,0),"h AM/PM") -> 11 AM | I13: =IF(OR('Merged raw data'!H13=1,'Merged raw data'!H13=2,'Merged raw data'!H13=3,'Merged raw data'!H13=4,'Merged raw data'!H13=5),"weekday","weekend") -> weekend | J13: Spring | K13: =IF('Merged raw data'!I13=1,"Clear",IF('Merged raw data'!I13=2,"Mist",IF('Merged raw data'!I13=3,"Rain",IF('Merged raw data'!I13=4,"Storm","NA")))) -> Clear | L13: 0.81 | M13: 0.2836 | N13: ='Merged raw data'!$J13*100 -> 36 | O13: 26 | P13: 30 | Q13: 56 | R13: =IF(Q13>=outliers!I15,"High",IF(Q13<=outliers!I14,"Low","Moderate")) -> High | S13: =IF(OR(Q13<outliers!$I$6,Q13>outliers!$I$7),"Outlier","Normal") -> Normal | T13: =IF(OR(L13<outliers!$J$6,L13>outliers!$J$7),"Outlier","Normal") -> Normal | U13: =IF(OR(M13<outliers!$K$6,M13>outliers!$K$7),"Outlier","Normal") -> Normal
... A1001: 1000 | B1001: 40588 | C1001: FALSE | D1001: =TEXT(B1001,"dddd") -> Monday | E1001: 0.303 | F1001: =YEAR('Merged raw data'!$B1001) -> 2011 | G1001: =TEXT('Merged raw data'!$B1001,"mmmm") -> February | H1001: =TEXT(TIME('Merged raw data'!F1001,0,0),"h AM/PM") -> 7 AM | I1001: =IF(OR('Merged raw data'!H1001=1,'Merged raw data'!H1001=2,'Merged raw data'!H1001=3,'Merged raw data'!H1001=4,'Merged raw data'!H1001=5),"weekday","weekend") -> weekday | J1001: Spring | K1001: =IF('Merged raw data'!I1001=1,"Clear",IF('Merged raw data'!I1001=2,"Mist",IF('Merged raw data'!I1001=3,"Rain",IF('Merged raw data'!I1001=4,"Storm","NA")))) -> Clear | L1001: 0.46 | M1001: 0.2985 | N1001: ='Merged raw data'!$J1001*100 -> 34 | O1001: 2 | P1001: 96 | Q1001: 98 | R1001: =IF(Q1001>=outliers!I1003,"High",IF(Q1001<=outliers!I1002,"Low","Moderate")) -> High | S1001: =IF(OR(Q1001<outliers!$I$6,Q1001>outliers!$I$7),"Outlier","Normal") -> Normal | T1001: =IF(OR(L1001<outliers!$J$6,L1001>outliers!$J$7),"Outlier","Normal") -> Normal | U1001: =IF(OR(M1001<outliers!$K$6,M1001>outliers!$K$7),"Outlier","Normal") -> Normal
O1003: 4921 | P1003: 53383 | Q1003: 58304

Sheet Merged raw data
A1: instant | B1: dteday | C1: season | D1: yr | E1: mnth | F1: hr | G1: holiday | H1: weekday | I1: weathersit | J1: temp | K1: atemp | L1: hum | M1: windspeed | N1: casual | O1: registered | P1: cnt
A2: 1 | B2: 40544 | C2: 1 | D2: 0 | E2: 1 | F2: 0 | G2: FALSE | H2: 6 | I2: 1 | J2: 0.24 | K2: 0.2879 | L2: 0.81 | M2: 0 | N2: 3 | O2: 13 | P2: 16
A3: 2 | B3: 40544 | C3: 1 | D3: 0 | E3: 1 | F3: 1 | G3: FALSE | H3: 6 | I3: 1 | J3: 0.22 | K3: 0.2727 | L3: 0.8 | M3: 0 | N3: 8 | O3: 32 | P3: 40
A4: 3 | B4: 40544 | C4: 1 | D4: 0 | E4: 1 | F4: 2 | G4: FALSE | H4: 6 | I4: 1 | J4: 0.22 | K4: 0.2727 | L4: 0.8 | M4: 0 | N4: 5 | O4: 27 | P4: 32
A5: 4 | B5: 40544 | C5: 1 | D5: 0 | E5: 1 | F5: 3 | G5: FALSE | H5: 6 | I5: 1 | J5: 0.24 | K5: 0.2879 | L5: 0.75 | M5: 0 | N5: 3 | O5: 10 | P5: 13
A6: 5 | B6: 40544 | C6: 1 | D6: 0 | E6: 1 | F6: 4 | G6: FALSE | H6: 6 | I6: 1 | J6: 0.24 | K6: 0.2879 | L6: 0.75 | M6: 0 | N6: 0 | O6: 1 | P6: 1
A7: 6 | B7: 40544 | C7: 1 | D7: 0 | E7: 1 | F7: 5 | G7: FALSE | H7: 6 | I7: 2 | J7: 0.24 | K7: 0.2576 | L7: 0.75 | M7: 0.0896 | N7: 0 | O7: 1 | P7: 1
A8: 7 | B8: 40544 | C8: 1 | D8: 0 | E8: 1 | F8: 6 | G8: FALSE | H8: 6 | I8: 1 | J8: 0.22 | K8: 0.2727 | L8: 0.8 | M8: 0 | N8: 2 | O8: 0 | P8: 2
A9: 8 | B9: 40544 | C9: 1 | D9: 0 | E9: 1 | F9: 7 | G9: FALSE | H9: 6 | I9: 1 | J9: 0.2 | K9: 0.2576 | L9: 0.86 | M9: 0 | N9: 1 | O9: 2 | P9: 3
A10: 9 | B10: 40544 | C10: 1 | D10: 0 | E10: 1 | F10: 8 | G10: FALSE | H10: 6 | I10: 1 | J10: 0.24 | L10: 0.75 | M10: 0 | N10: 1 | O10: 7 | P10: 8
A11: 10 | B11: 40544 | C11: 1 | D11: 0 | E11: 1 | F11: 9 | G11: FALSE | H11: 6 | I11: 1 | J11: 0.32 | K11: 0.3485 | L11: 0.76 | M11: 0 | N11: 8 | O11: 6 | P11: 14
A12: 11 | B12: 40544 | C12: 1 | D12: 0 | E12: 1 | F12: 10 | G12: FALSE | H12: 6 | I12: 1 | J12: 0.38 | K12: 0.3939 | L12: 0.76 | M12: 0.2537 | N12: 12 | O12: 24 | P12: 36
A13: 12 | B13: 40544 | C13: 1 | D13: 0 | E13: 1 | F13: 11 | G13: FALSE | H13: 6 | I13: 1 | J13: 0.36 | K13: 0.3333 | L13: 0.81 | M13: 0.2836 | N13: 26 | O13: 30 | P13: 56
A14: 13 | B14: 40544 | C14: 1 | D14: 0 | E14: 1 | F14: 12 | G14: FALSE | H14: 6 | I14: 1 | J14: 0.42 | K14: 0.4242 | L14: 0.77 | M14: 0.2836 | N14: 29 | O14: 55 | P14: 84
A15: 14 | B15: 40544 | C15: 1 | D15: 0 | E15: 1 | F15: 13 | G15: FALSE | H15: 6 | I15: 2 | J15: 0.46 | K15: 0.4545 | L15: 0.72 | M15: 0.2985 | N15: 47 | O15: 47 | P15: 94
A16: 15 | B16: 40544 | C16: 1 | D16: 0 | E16: 1 | F16: 14 | G16: FALSE | H16: 6 | I16: 2 | J16: 0.46 | K16: 0.4545 | L16: 0.72 | M16: 0.2836 | N16: 35 | O16: 71 | P16: 106
A17: 16 | B17: 40544 | C17: 1 | D17: 0 | E17: 1 | F17: 15 | G17: FALSE | H17: 6 | I17: 2 | J17: 0.44 | K17: 0.4394 | L17: 0.77 | M17: 0.2985 | N17: 40 | O17: 70 | P17: 110
A18: 17 | B18: 40544 | C18: 1 | D18: 0 | E18: 1 | F18: 16 | G18: FALSE | H18: 6 | I18: 2 | J18: 0.42 | K18: 0.4242 | L18: 0.82 | M18: 0.2985 | N18: 41 | O18: 52 | P18: 93
A19: 18 | B19: 40544 | C19: 1 | D19: 0 | E19: 1 | F19: 17 | G19: FALSE | H19: 6 | I19: 2 | J19: 0.44 | L19: 0.82 | M19: 0.2836 | N19: 15 | O19: 52 | P19: 67
A20: 19 | B20: 40544 | C20: 1 | D20: 0 | E20: 1 | F20: 18 | G20: FALSE | H20: 6 | I20: 3 | J20: 0.42 | K20: 0.4242 | L20: 0.88 | M20: 0.2537 | N20: 9 | O20: 26 | P20: 35
A21: 20 | B21: 40544 | C21: 1 | D21: 0 | E21: 1 | F21: 19 | G21: FALSE | H21: 6 | I21: 3 | J21: 0.42 | K21: 0.4242 | L21: 0.88 | M21: 0.2537 | N21: 6 | O21: 31 | P21: 37
A22: 21 | B22: 40544 | C22: 1 | D22: 0 | E22: 1 | F22: 20 | G22: FALSE | H22: 6 | I22: 2 | J22: 0.4 | K22: 0.4091 | L22: 0.87 | M22: 0.2537 | N22: 11 | O22: 25 | P22: 36
A23: 22 | B23: 40544 | C23: 1 | D23: 0 | E23: 1 | F23: 21 | G23: FALSE | H23: 6 | I23: 2 | J23: 0.4 | K23: 0.4091 | L23: 0.87 | M23: 0.194 | N23: 3 | O23: 31 | P23: 34
A24: 23 | B24: 40544 | C24: 1 | D24: 0 | E24: 1 | F24: 22 | G24: FALSE | H24: 6 | I24: 2 | J24: 0.4 | K24: 0.4091 | L24: 0.94 | M24: 0.2239 | N24: 11 | O24: 17 | P24: 28
A25: 24 | B25: 40544 | C25: 1 | D25: 0 | E25: 1 | F25: 23 | G25: FALSE | H25: 6 | I25: 2 | J25: 0.46 | L25: 0.88 | M25: 0.2985 | N25: 15 | O25: 24 | P25: 39
A26: 25 | B26: 40545 | C26: 1 | D26: 0 | E26: 1 | F26: 0 | G26: FALSE | H26: 0 | I26: 2 | J26: 0.46 | K26: 0.4545 | L26: 0.88 | M26: 0.2985 | N26: 4 | O26: 13 | P26: 17
A27: 26 | B27: 40545 | C27: 1 | D27: 0 | E27: 1 | F27: 1 | G27: FALSE | H27: 0 | I27: 2 | J27: 0.44 | K27: 0.4394 | L27: 0.94 | M27: 0.2537 | N27: 1 | O27: 16 | P27: 17
A28: 27 | B28: 40545 | C28: 1 | D28: 0 | E28: 1 | F28: 2 | G28: FALSE | H28: 0 | I28: 2 | J28: 0.42 | K28: 0.4242 | L28: 1 | M28: 0.2836 | N28: 1 | O28: 8 | P28: 9
A29: 28 | B29: 40545 | C29: 1 | D29: 0 | E29: 1 | F29: 3 | G29: FALSE | H29: 0 | I29: 2 | J29: 0.46 | K29: 0.4545 | L29: 0.94 | M29: 0.194 | N29: 2 | O29: 4 | P29: 6
A30: 29 | B30: 40545 | C30: 1 | D30: 0 | E30: 1 | F30: 4 | G30: FALSE | H30: 0 | I30: 2 | J30: 0.46 | L30: 0.94 | M30: 0.194 | N30: 2 | O30: 1 | P30: 3
A31: 30 | B31: 40545 | C31: 1 | D31: 0 | E31: 1 | F31: 6 | G31: FALSE | H31: 0 | I31: 3 | J31: 0.42 | K31: 0.4242 | L31: 0.77 | M31: 0.2985 | N31: 0 | O31: 2 | P31: 2
A32: 31 | B32: 40545 | C32: 1 | D32: 0 | E32: 1 | F32: 7 | G32: FALSE | H32: 0 | I32: 2 | J32: 0.4 | K32: 0.4091 | L32: 0.76 | M32: 0.194 | N32: 0 | O32: 1 | P32: 1
A33: 32 | B33: 40545 | C33: 1 | D33: 0 | E33: 1 | F33: 8 | G33: FALSE | H33: 0 | I33: 3 | J33: 0.4 | K33: 0.4091 | L33: 0.71 | M33: 0.2239 | N33: 0 | O33: 8 | P33: 8
A34: 33 | B34: 40545 | C34: 1 | D34: 0 | E34: 1 | F34: 9 | G34: FALSE | H34: 0 | I34: 2 | J34: 0.38 | L34: 0.76 | M34: 0.2239 | N34: 1 | O34: 19 | P34: 20
A35: 34 | B35: 40545 | C35: 1 | D35: 0 | E35: 1 | F35: 10 | G35: FALSE | H35: 0 | I35: 2 | J35: 0.36 | K35: 0.3485 | L35: 0.81 | M35: 0.2239 | N35: 7 | O35: 46 | P35: 53
A36: 35 | B36: 40545 | C36: 1 | D36: 0 | E36: 1 | F36: 11 | G36: FALSE | H36: 0 | I36: 2 | J36: 0.36 | K36: 0.3333 | L36: 0.71 | M36: 0.2537 | N36: 16 | O36: 54 | P36: 70
A37: 36 | B37: 40545 | C37: 1 | D37: 0 | E37: 1 | F37: 12 | G37: FALSE | H37: 0 | I37: 2 | J37: 0.36 | K37: 0.3333 | L37: 0.66 | M37: 0.2985 | N37: 20 | O37: 73 | P37: 93
A38: 37 | B38: 40545 | C38: 1 | D38: 0 | E38: 1 | F38: 13 | G38: FALSE | H38: 0 | I38: 2 | J38: 0.36 | K38: 0.3485 | L38: 0.66 | M38: 0.1343 | N38: 11 | O38: 64 | P38: 75
A39: 38 | B39: 40545 | C39: 1 | D39: 0 | E39: 1 | F39: 14 | G39: FALSE | H39: 0 | I39: 3 | J39: 0.36 | L39: 0.76 | M39: 0.194 | N39: 4 | O39: 55 | P39: 59
A40: 39 | B40: 40545 | C40: 1 | D40: 0 | E40: 1 | F40: 15 | G40: FALSE | H40: 0 | I40: 3 | J40: 0.34 | K40: 0.3333 | L40: 0.81 | M40: 0.1642 | N40: 19 | O40: 55 | P40: 74
...

Sheet outliers
G2: Outlier Calculation | H2: Value | I2: Count | J2: Humidity | K2: windspeed
G3: Q1 | H3: =QUARTILE.INC(Table1[cnt],1) | I3: =_xlfn.QUARTILE.INC('working data'!$Q$2:$Q$1001,1) -> 16 | J3: =_xlfn.QUARTILE.INC('working data'!$L$2:$L$1001,1) -> 0.44 | K3: =_xlfn.QUARTILE.INC('working data'!$M$2:$M$1001,1) -> 0.1343
G4: Q3 | H4: =QUARTILE.INC(Table1[cnt],3) | I4: =_xlfn.QUARTILE.INC('working data'!$Q$2:$Q$1001,3) -> 83 | J4: =_xlfn.QUARTILE.INC('working data'!$L$2:$L$1001,3) -> 0.7 | K4: =_xlfn.QUARTILE.INC('working data'!$M$2:$M$1001,3) -> 0.2836
G5: IQR | H5: Q3-Q1 | I5: =I4-I3 -> 67 | J5: =J4-J3 -> 0.26 | K5: =K4-K3 -> 0.1493
G6: Lower Limit | H6: Q1-(1.5*IQR) | I6: =I3-(1.5*I5) -> -84.5 | J6: =J3-(1.5*J5) -> 0.05 | K6: =K3-(1.5*K5) -> -0.08965
G7: Upper Limit | H7: Q3+(1.5*IQR) | I7: =I4+(1.5*I5) -> 183.5 | J7: =J4+(1.5*J5) -> 1.09 | K7: =K4+(1.5*K5) -> 0.50755

Sheet dataset_3
A1: instant | B1: dteday | C1: season | D1: yr | E1: mnth | F1: hr | G1: holiday | H1: weekday | I1: weathersit | J1: temp | K1: atemp | L1: hum | M1: windspeed | N1: casual | O1: registered | P1: cnt
A2: 611 | B2: 40571 | C2: 1 | D2: 0 | E2: 1 | F2: 16 | G2: FALSE | H2: 5 | I2: 1 | J2: 0.22 | K2: 0.2727 | L2: 0.8 | M2: 0 | N2: 10 | O2: 70 | P2: 80
A3: 612 | B3: 40571 | C3: 1 | D3: 0 | E3: 1 | F3: 17 | G3: FALSE | H3: 5 | I3: 1 | J3: 0.24 | K3: 0.2424 | L3: 0.75 | M3: 0.1343 | N3: 2 | O3: 147 | P3: 149
A4: 613 | B4: 40571 | C4: 1 | D4: 0 | E4: 1 | F4: 18 | G4: FALSE | H4: 5 | I4: 1 | J4: 0.24 | K4: 0.2273 | L4: 0.75 | M4: 0.194 | N4: 2 | O4: 107 | P4: 109
A5: 614 | B5: 40571 | C5: 1 | D5: 0 | E5: 1 | F5: 19 | G5: FALSE | H5: 5 | I5: 2 | J5: 0.24 | K5: 0.2424 | L5: 0.75 | M5: 0.1343 | N5: 5 | O5: 84 | P5: 89
A6: 615 | B6: 40571 | C6: 1 | D6: 0 | E6: 1 | F6: 20 | G6: FALSE | H6: 5 | I6: 2 | J6: 0.24 | K6: 0.2273 | L6: 0.7 | M6: 0.194 | N6: 1 | O6: 61 | P6: 62
A7: 616 | B7: 40571 | C7: 1 | D7: 0 | E7: 1 | F7: 21 | G7: FALSE | H7: 5 | I7: 2 | J7: 0.22 | K7: 0.2273 | L7: 0.75 | M7: 0.1343 | N7: 1 | O7: 57 | P7: 58
A8: 617 | B8: 40571 | C8: 1 | D8: 0 | E8: 1 | F8: 22 | G8: FALSE | H8: 5 | I8: 1 | J8: 0.24 | K8: 0.2121 | L8: 0.65 | M8: 0.3582 | N8: 0 | O8: 26 | P8: 26
A9: 618 | B9: 40571 | C9: 1 | D9: 0 | E9: 1 | F9: 23 | G9: FALSE | H9: 5 | I9: 1 | J9: 0.24 | K9: 0.2273 | L9: 0.6 | M9: 0.2239 | N9: 1 | O9: 22 | P9: 23
A10: 619 | B10: 40572 | C10: 1 | D10: 0 | E10: 1 | F10: 0 | G10: FALSE | H10: 6 | I10: 1 | J10: 0.22 | K10: 0.197 | L10: 0.64 | M10: 0.3582 | N10: 2 | O10: 26 | P10: 28
A11: 620 | B11: 40572 | C11: 1 | D11: 0 | E11: 1 | F11: 1 | G11: FALSE | H11: 6 | I11: 1 | J11: 0.22 | K11: 0.2273 | L11: 0.64 | M11: 0.194 | N11: 0 | O11: 20 | P11: 20
A12: 621 | B12: 40572 | C12: 1 | D12: 0 | E12: 1 | F12: 2 | G12: FALSE | H12: 6 | I12: 1 | J12: 0.22 | K12: 0.2273 | L12: 0.64 | M12: 0.1642 | N12: 0 | O12: 15 | P12: 15
A13: 622 | B13: 40572 | C13: 1 | D13: 0 | E13: 1 | F13: 3 | G13: FALSE | H13: 6 | I13: 1 | J13: 0.2 | K13: 0.2121 | L13: 0.64 | M13: 0.1343 | N13: 3 | O13: 5 | P13: 8
... A391: 1000 | B391: 40588 | C391: 1 | D391: 0 | E391: 2 | F391: 7 | G391: FALSE | H391: 1 | I391: 1 | J391: 0.34 | K391: 0.303 | L391: 0.46 | M391: 0.2985 | N391: 2 | O391: 96 | P391: 98

Sheet Merge1
A1: instant | B1: dteday | C1: season | D1: yr | E1: mnth | F1: hr | G1: holiday | H1: weekday | I1: weathersit | J1: temp | K1: atemp | L1: hum | M1: windspeed | N1: casual | O1: registered | P1: cnt
A2: 1 | B2: 40544 | C2: 1 | D2: 0 | E2: 1 | F2: 0 | G2: FALSE | H2: 6 | I2: 1 | J2: 0.24 | K2: 0.2879 | L2: 0.81 | M2: 0 | N2: 3 | O2: 13 | P2: 16
A3: 2 | B3: 40544 | C3: 1 | D3: 0 | E3: 1 | F3: 1 | G3: FALSE | H3: 6 | I3: 1 | J3: 0.22 | K3: 0.2727 | L3: 0.8 | M3: 0 | N3: 8 | O3: 32 | P3: 40
A4: 3 | B4: 40544 | C4: 1 | D4: 0 | E4: 1 | F4: 2 | G4: FALSE | H4: 6 | I4: 1 | J4: 0.22 | K4: 0.2727 | L4: 0.8 | M4: 0 | N4: 5 | O4: 27 | P4: 32
A5: 4 | B5: 40544 | C5: 1 | D5: 0 | E5: 1 | F5: 3 | G5: FALSE | H5: 6 | I5: 1 | J5: 0.24 | K5: 0.2879 | L5: 0.75 | M5: 0 | N5: 3 | O5: 10 | P5: 13
A6: 5 | B6: 40544 | C6: 1 | D6: 0 | E6: 1 | F6: 4 | G6: FALSE | H6: 6 | I6: 1 | J6: 0.24 | K6: 0.2879 | L6: 0.75 | M6: 0 | N6: 0 | O6: 1 | P6: 1
A7: 6 | B7: 40544 | C7: 1 | D7: 0 | E7: 1 | F7: 5 | G7: FALSE | H7: 6 | I7: 2 | J7: 0.24 | K7: 0.2576 | L7: 0.75 | M7: 0.0896 | N7: 0 | O7: 1 | P7: 1
A8: 7 | B8: 40544 | C8: 1 | D8: 0 | E8: 1 | F8: 6 | G8: FALSE | H8: 6 | I8: 1 | J8: 0.22 | K8: 0.2727 | L8: 0.8 | M8: 0 | N8: 2 | O8: 0 | P8: 2
A9: 8 | B9: 40544 | C9: 1 | D9: 0 | E9: 1 | F9: 7 | G9: FALSE | H9: 6 | I9: 1 | J9: 0.2 | K9: 0.2576 | L9: 0.86 | M9: 0 | N9: 1 | O9: 2 | P9: 3
A10: 9 | B10: 40544 | C10: 1 | D10: 0 | E10: 1 | F10: 8 | G10: FALSE | H10: 6 | I10: 1 | J10: 0.24 | L10: 0.75 | M10: 0 | N10: 1 | O10: 7 | P10: 8
A11: 10 | B11: 40544 | C11: 1 | D11: 0 | E11: 1 | F11: 9 | G11: FALSE | H11: 6 | I11: 1 | J11: 0.32 | K11: 0.3485 | L11: 0.76 | M11: 0 | N11: 8 | O11: 6 | P11: 14
A12: 11 | B12: 40544 | C12: 1 | D12: 0 | E12: 1 | F12: 10 | G12: FALSE | H12: 6 | I12: 1 | J12: 0.38 | K12: 0.3939 | L12: 0.76 | M12: 0.2537 | N12: 12 | O12: 24 | P12: 36
A13: 12 | B13: 40544 | C13: 1 | D13: 0 | E13: 1 | F13: 11 | G13: FALSE | H13: 6 | I13: 1 | J13: 0.36 | K13: 0.3333 | L13: 0.81 | M13: 0.2836 | N13: 26 | O13: 30 | P13: 56
A14: 13 | B14: 40544 | C14: 1 | D14: 0 | E14: 1 | F14: 12 | G14: FALSE | H14: 6 | I14: 1 | J14: 0.42 | K14: 0.4242 | L14: 0.77 | M14: 0.2836 | N14: 29 | O14: 55 | P14: 84
A15: 14 | B15: 40544 | C15: 1 | D15: 0 | E15: 1 | F15: 13 | G15: FALSE | H15: 6 | I15: 2 | J15: 0.46 | K15: 0.4545 | L15: 0.72 | M15: 0.2985 | N15: 47 | O15: 47 | P15: 94
A16: 15 | B16: 40544 | C16: 1 | D16: 0 | E16: 1 | F16: 14 | G16: FALSE | H16: 6 | I16: 2 | J16: 0.46 | K16: 0.4545 | L16: 0.72 | M16: 0.2836 | N16: 35 | O16: 71 | P16: 106
A17: 16 | B17: 40544 | C17: 1 | D17: 0 | E17: 1 | F17: 15 | G17: FALSE | H17: 6 | I17: 2 | J17: 0.44 | K17: 0.4394 | L17: 0.77 | M17: 0.2985 | N17: 40 | O17: 70 | P17: 110
A18: 17 | B18: 40544 | C18: 1 | D18: 0 | E18: 1 | F18: 16 | G18: FALSE | H18: 6 | I18: 2 | J18: 0.42 | K18: 0.4242 | L18: 0.82 | M18: 0.2985 | N18: 41 | O18: 52 | P18: 93
A19: 18 | B19: 40544 | C19: 1 | D19: 0 | E19: 1 | F19: 17 | G19: FALSE | H19: 6 | I19: 2 | J19: 0.44 | L19: 0.82 | M19: 0.2836 | N19: 15 | O19: 52 | P19: 67
A20: 19 | B20: 40544 | C20: 1 | D20: 0 | E20: 1 | F20: 18 | G20: FALSE | H20: 6 | I20: 3 | J20: 0.42 | K20: 0.4242 | L20: 0.88 | M20: 0.2537 | N20: 9 | O20: 26 | P20: 35
A21: 20 | B21: 40544 | C21: 1 | D21: 0 | E21: 1 | F21: 19 | G21: FALSE | H21: 6 | I21: 3 | J21: 0.42 | K21: 0.4242 | L21: 0.88 | M21: 0.2537 | N21: 6 | O21: 31 | P21: 37
A22: 21 | B22: 40544 | C22: 1 | D22: 0 | E22: 1 | F22: 20 | G22: FALSE | H22: 6 | I22: 2 | J22: 0.4 | K22: 0.4091 | L22: 0.87 | M22: 0.2537 | N22: 11 | O22: 25 | P22: 36
A23: 22 | B23: 40544 | C23: 1 | D23: 0 | E23: 1 | F23: 21 | G23: FALSE | H23: 6 | I23: 2 | J23: 0.4 | K23: 0.4091 | L23: 0.87 | M23: 0.194 | N23: 3 | O23: 31 | P23: 34
A24: 23 | B24: 40544 | C24: 1 | D24: 0 | E24: 1 | F24: 22 | G24: FALSE | H24: 6 | I24: 2 | J24: 0.4 | K24: 0.4091 | L24: 0.94 | M24: 0.2239 | N24: 11 | O24: 17 | P24: 28
A25: 24 | B25: 40544 | C25: 1 | D25: 0 | E25: 1 | F25: 23 | G25: FALSE | H25: 6 | I25: 2 | J25: 0.46 | L25: 0.88 | M25: 0.2985 | N25: 15 | O25: 24 | P25: 39
A26: 25 | B26: 40545 | C26: 1 | D26: 0 | E26: 1 | F26: 0 | G26: FALSE | H26: 0 | I26: 2 | J26: 0.46 | K26: 0.4545 | L26: 0.88 | M26: 0.2985 | N26: 4 | O26: 13 | P26: 17
A27: 26 | B27: 40545 | C27: 1 | D27: 0 | E27: 1 | F27: 1 | G27: FALSE | H27: 0 | I27: 2 | J27: 0.44 | K27: 0.4394 | L27: 0.94 | M27: 0.2537 | N27: 1 | O27: 16 | P27: 17
A28: 27 | B28: 40545 | C28: 1 | D28: 0 | E28: 1 | F28: 2 | G28: FALSE | H28: 0 | I28: 2 | J28: 0.42 | K28: 0.4242 | L28: 1 | M28: 0.2836 | N28: 1 | O28: 8 | P28: 9
A29: 28 | B29: 40545 | C29: 1 | D29: 0 | E29: 1 | F29: 3 | G29: FALSE | H29: 0 | I29: 2 | J29: 0.46 | K29: 0.4545 | L29: 0.94 | M29: 0.194 | N29: 2 | O29: 4 | P29: 6
A30: 29 | B30: 40545 | C30: 1 | D30: 0 | E30: 1 | F30: 4 | G30: FALSE | H30: 0 | I30: 2 | J30: 0.46 | L30: 0.94 | M30: 0.194 | N30: 2 | O30: 1 | P30: 3
A31: 30 | B31: 40545 | C31: 1 | D31: 0 | E31: 1 | F31: 6 | G31: FALSE | H31: 0 | I31: 3 | J31: 0.42 | K31: 0.4242 | L31: 0.77 | M31: 0.2985 | N31: 0 | O31: 2 | P31: 2
A32: 31 | B32: 40545 | C32: 1 | D32: 0 | E32: 1 | F32: 7 | G32: FALSE | H32: 0 | I32: 2 | J32: 0.4 | K32: 0.4091 | L32: 0.76 | M32: 0.194 | N32: 0 | O32: 1 | P32: 1
A33: 32 | B33: 40545 | C33: 1 | D33: 0 | E33: 1 | F33: 8 | G33: FALSE | H33: 0 | I33: 3 | J33: 0.4 | K33: 0.4091 | L33: 0.71 | M33: 0.2239 | N33: 0 | O33: 8 | P33: 8
A34: 33 | B34: 40545 | C34: 1 | D34: 0 | E34: 1 | F34: 9 | G34: FALSE | H34: 0 | I34: 2 | J34: 0.38 | L34: 0.76 | M34: 0.2239 | N34: 1 | O34: 19 | P34: 20
A35: 34 | B35: 40545 | C35: 1 | D35: 0 | E35: 1 | F35: 10 | G35: FALSE | H35: 0 | I35: 2 | J35: 0.36 | K35: 0.3485 | L35: 0.81 | M35: 0.2239 | N35: 7 | O35: 46 | P35: 53
A36: 35 | B36: 40545 | C36: 1 | D36: 0 | E36: 1 | F36: 11 | G36: FALSE | H36: 0 | I36: 2 | J36: 0.36 | K36: 0.3333 | L36: 0.71 | M36: 0.2537 | N36: 16 | O36: 54 | P36: 70
A37: 36 | B37: 40545 | C37: 1 | D37: 0 | E37: 1 | F37: 12 | G37: FALSE | H37: 0 | I37: 2 | J37: 0.36 | K37: 0.3333 | L37: 0.66 | M37: 0.2985 | N37: 20 | O37: 73 | P37: 93
A38: 37 | B38: 40545 | C38: 1 | D38: 0 | E38: 1 | F38: 13 | G38: FALSE | H38: 0 | I38: 2 | J38: 0.36 | K38: 0.3485 | L38: 0.66 | M38: 0.1343 | N38: 11 | O38: 64 | P38: 75
A39: 38 | B39: 40545 | C39: 1 | D39: 0 | E39: 1 | F39: 14 | G39: FALSE | H39: 0 | I39: 3 | J39: 0.36 | L39: 0.76 | M39: 0.194 | N39: 4 | O39: 55 | P39: 59
A40: 39 | B40: 40545 | C40: 1 | D40: 0 | E40: 1 | F40: 15 | G40: FALSE | H40: 0 | I40: 3 | J40: 0.34 | K40: 0.3333 | L40: 0.81 | M40: 0.1642 | N40: 19 | O40: 55 | P40: 74
...
